Workbook

Sheet חציון ב
A1: טבלת תורנויות אנשי קבע מחנה לוט"ם | S1: אדרת
S2: מעוף
S3: משא"ן
S4: הטמעה והפעלה
S5: מצו"ב
A6: חציון ב' - 2026 | S6: בטחון מידע
A7: קצין תורן מחנה לוט"ם- סג"ם,סגן,סרן | S7: אמל"ח
S8: ליד
A9: תאריך | B9: יום | C9: מחלקה | D9: שם | E9: משפחה | F9: דרגה | G9: טלפון | H9: הערות | S9: ענף שדה
A10: 46204 | B10: רביעי | C10: ליד | S10: מצפ"ן
A11: 02-04/07/2026 | B11: סופש | C11: מצו"ב
A12: 46208 | B12: ראשון | C12: מעוף | S12: לוגיסטיקה
A13: 46209 | B13: שני | C13: ליד
A14: 46210 | B14: שלישי | C14: מצפ"ן | S14: אומ"ן
A15: 46211 | B15: רביעי | C15: מצו"ב | S15: התרעה
A16: 09-11/07/2026 | B16: סופש | C16: מעוף | S16: ענף שהם
A17: 46215 | B17: ראשון | C17: מצו"ב
A18: 46216 | B18: שני | C18: מעוף
A19: 46217 | B19: שלישי | C19: ליד
A20: 46218 | B20: רביעי | C20: מצו"ב
A21: 16-18/07/2026 | B21: סופש | C21: מעוף
A22: 46222 | B22: ראשון | C22: מצו"ב
A23: 46223 | B23: שני | C23: משא"ן
A24: 46224 | B24: שלישי | C24: מעוף
A25: 46225 | B25: רביעי | C25: ליד
A26: 23-25/07/2026 | B26: סופש | C26: מצו"ב
A27: 46229 | B27: ראשון | C27: מעוף
A28: 46230 | B28: שני | C28: מצו"ב
A29: 46231 | B29: שלישי | C29: מצו"ב
A30: 46232 | B30: רביעי | C30: ליד
A31: 30.7-01.08/2026 | B31: סופש | C31: מעוף
A32: 46236 | B32: ראשון | C32: מצו"ב
A33: 46237 | B33: שני | C33: מצו"ב
A34: 46238 | B34: שלישי | C34: מעוף
A35: 46239 | B35: רביעי | C35: ליד
A36: 06-08/08/2026 | B36: סופש | C36: ליד
A37: 46243 | B37: ראשון | C37: מצו"ב
A38: 46244 | B38: שני | C38: ליד
A39: 46245 | B39: שלישי | C39: מצפ"ן
A40: 46246 | B40: רביעי | C40: מצו"ב
...

Sheet בדיקת הקצאות כלל לוט"ם
A3: אגף | B3: קצין לוט"ם | C3: נגד לוט"ם | D3: מפקד 782 | E3: קצין 782 | F3: תורן שער+טרמפיאדות | I3: מחלקה | J3: נתונים גולמיים | L3: הקצאות מחושבות | O3: הקצאות בפועל | R3: סה"כ מיצוי | X3: =COUNTIFS(#REF!,I6) -> #REF!
A4: ליד | B4: 30 | C4: 21 | D4: 20 | E4: 31 | F4: 2 | J4: תפקיד | K4: פוטנציאל | L4: חול | M4: שבת/חג | N4: סה"כ | O4: חול | P4: שישי-שבת | Q4: סה"כ | R4: קצין | S4: נגד | T4: רס"ן | U4: קצין ידין | V4: תורן שער+טרמפיאדות
A5: אדרת | B5: 1 | C5: 2 | D5: 2 | E5: 1 | F5: 0 | I5: ליד | J5: קצין לוטם | K5: =B$4 -> 30 | L5: =$B$22*$K5/$B$18 -> 22.014388 | M5: =$D$22*$K5/$B$18 -> 6.2589928 | N5: =SUM(L5:M5) -> 28.273381 | O5: =COUNTIF('חציון ב'!$C$10:$C$136,$I$5)-$P$5 -> 21 | P5: =COUNTIFS('חציון ב'!$C$10:$C$136,$I$5,'חציון ב'!$B$10:$B$136,$A$43)+COUNTIFS('חציון ב'!$C$10:$C$136,$I$5,'חציון ב'!$B$10:$B$136,$A$42) -> 6 | Q5: =SUM(O5:P5) -> 27 | R5: =IF(N5,Q5/N5,#N/A) -> 0.95496183 | S5: =IF(N6,Q6/N6,#N/A) -> 1.0134497 | T5: =IF(N7,Q7/N7,#N/A) -> 0.9581749 | U5: =IF(N8,Q8/N8,#N/A) -> 0.72284398 | V5: =IF(N9,Q9/N9,#N/A) -> 1.5294118
A6: מעוף | B6: 37 | C6: 42 | D6: 18 | E6: 40 | F6: 8 | J6: נגד לוטם | K6: =C$4 -> 21 | L6: =$B$23*$K6/$C$18 -> 13.060976 | M6: =$D$23*$K6/$C$18 -> 3.7134146 | N6: =SUM(L6:M6) -> 16.77439 | O6: 13 | P6: =COUNTIFS('חציון ב'!$C$145:$C$271,$I$5,'חציון ב'!$B$145:$B$271,$A$43)+COUNTIFS('חציון ב'!$C$145:$C$271,$I$5,'חציון ב'!$B$145:$B$271,$A$42) -> 4 | Q6: =SUM(O6:P6) -> 17
A7: משא"ן | B7: 5 | C7: 0 | D7: 0 | E7: 5 | F7: 2 | J7: מפקד 782 | K7: =D$4 -> 20 | L7: 11.5 | M7: =$D$24*$K7/$D$18 -> 3.1111111 | N7: =SUM(L7:M7) -> 14.611111 | O7: 12 | P7: 2 | Q7: =SUM(O7:P7) -> 14
A8: מצו"ב | B8: 58 | C8: 81 | D8: 45 | E8: 37 | F8: 32 | J8: ק.תורן 782 | K8: =E$4 -> 31 | L8: =$B$25*E$4/$E$18 -> 9.6557377 | M8: =$D$25*$K8/$E$18 -> 2.795082 | N8: =SUM(L8:M8) -> 12.45082 | O8: 7 | P8: 2 | Q8: =SUM(O8:P8) -> 9
A9: בטחון מידע | B9: 0 | C9: 0 | D9: 0 | E9: 0 | F9: 0 | J9: תורן שער+טרמפיאדות | K9: =F$4 -> 2 | L9: =$B$26*$K9/$F$18 -> 1.9615385 | M9: =$D$26*$K9/$F$18 -> 0 | N9: =SUM(L9:M9) -> 1.9615385 | O9: 3 | P9: =COUNTIFS('חציון ב'!$C$397:$C$447,$I$5,'חציון ב'!$B$397:$B$447,$A$43)+COUNTIFS('חציון ב'!$C$397:$C$447,$I$5,'חציון ב'!$B$397:$B$447,$A$42) -> 0 | Q9: =SUM(O9:P9) -> 3
A10: ממר"ם | B10: 0 | C10: 0 | D10: 0 | E10: 0 | F10: 0 | J10: סה"כ | K10: =SUM(K5:K9) -> 104 | L10: =SUM(L5:L9) -> 58.19264 | M10: =SUM(M5:M9) -> 15.878601 | N10: =SUM(L10:M10) -> 74.071241 | O10: =SUM(O5:O9) -> 56 | P10: =SUM(P5:P9) -> 14 | Q10: =SUM(Q5:Q9) -> 70
A11: ענף שדה | B11: 0 | C11: 0 | D11: 0 | E11: 0 | F11: 0 | I11: אדרת | J11: קצין לוטם | K11: =B$5 -> 1 | L11: =$B$22*$K11/$B$18 -> 0.73381295 | M11: =$D$22*$K11/$B$18 -> 0.20863309 | N11: =SUM(L11:M11) -> 0.94244604 | O11: =COUNTIF('חציון ב'!$C$10:$C$136,$I$11)-$P$11 -> 1 | P11: =COUNTIFS('חציון ב'!$C$10:$C$136,$I$11,'חציון ב'!$B$10:$B$136,$A$43)+COUNTIFS('חציון ב'!$C$10:$C$136,$I$11,'חציון ב'!$B$10:$B$136,$A$42) -> 0 | Q11: =SUM(O11:P11) -> 1 | R11: =IF(N11,Q11/N11,#N/A) -> 1.0610687 | S11: =IF(N12,Q12/N12,#N/A) -> 1.2519084 | T11: =IF(N13,Q13/N13,#N/A) -> #REF! | U11: =IF(N14,Q14/N14,#N/A) -> 0 | V11: =IF(N15,Q15/N15,#N/A) -> #N/A
A12: מצפן | B12: 7 | C12: 15 | D12: 5 | E12: 7 | F12: 1 | J12: נגד לוטם | K12: =C$5 -> 2 | L12: =$B$23*$K12/$C$18 -> 1.2439024 | M12: =$D$23*$K12/$C$18 -> 0.35365854 | N12: =SUM(L12:M12) -> 1.597561 | O12: =COUNTIF('חציון ב'!$C$145:$C$271,$I$11)-$P$12 -> 1 | P12: =COUNTIFS('חציון ב'!$C$145:$C$271,$I$11,'חציון ב'!$B$145:$B$271,$A$43)+COUNTIFS('חציון ב'!$C$145:$C$271,$I$11,'חציון ב'!$B$145:$B$271,$A$42) -> 1 | Q12: =SUM(O12:P12) -> 2
A13: ענף שהם | B13: 0 | C13: 0 | D13: 0 | E13: 0 | F13: 2 | J13: מפקד 782 | K13: =D$5 -> 2 | L13: =$B$24*$K13/$D$18 -> 1.1111111 | M13: =$D$24*$K13/$D$18 -> 0.31111111 | N13: =SUM(L13:M13) -> 1.4222222 | O13: =COUNTIF('חציון ב'!#REF!,$I$11)-$P$13 -> #REF! | P13: =COUNTIFS('חציון ב'!#REF!,$I$11,'חציון ב'!#REF!,$A$43)+COUNTIFS('חציון ב'!#REF!,$I$11,'חציון ב'!#REF!,$A$42) -> #REF! | Q13: =SUM(O13:P13) -> #REF!
A14: לוגיסטיקה | B14: 0 | C14: 0 | D14: 0 | E14: 0 | F14: 5 | J14: ק.תורן 782 | K14: =E$5 -> 1 | L14: =$B$25*E$5/$E$18 -> 0.31147541 | M14: =$D$25*$K14/$E$18 -> 0.090163934 | N14: =SUM(L14:M14) -> 0.40163934 | O14: =COUNTIF('חציון ב'!$L$144:$L$231,$I$11)-$P$14 -> 0 | P14: =COUNTIFS('חציון ב'!$L$144:$L$231,$I$11,'חציון ב'!$K$144:$K$231,$A$43)+COUNTIFS('חציון ב'!$L$144:$L$231,$I$11,'חציון ב'!$K$144:$K$231,$A$42) -> 0 | Q14: =SUM(O14:P14) -> 0
A15: התרעה | B15: 1 | C15: 3 | D15: 0 | E15: 1 | F15: 0 | J15: תורן שער+טרמפיאדות | K15: =F$5 -> 0 | L15: =$B$26*$K15/$F$18 -> 0 | M15: =$D$26*$K15/$F$18 -> 0 | N15: =SUM(L15:M15) -> 0 | O15: =COUNTIF('חציון ב'!$C$397:$C$433,$I$11)-$P$15 -> 0 | P15: =COUNTIFS('חציון ב'!$C$397:$C$447,$I$11,'חציון ב'!$B$397:$B$447,$A$43)+COUNTIFS('חציון ב'!$C$397:$C$447,$I$11,'חציון ב'!$B$397:$B$447,$A$42) -> 0 | Q15: =SUM(O15:P15) -> 0
J16: סה"כ | K16: =SUM(K11:K15) -> 6 | L16: =SUM(L11:L15) -> 3.4003019 | M16: =SUM(M11:M15) -> 0.96356668 | N16: =SUM(L16:M16) -> 4.3638686 | O16: =SUM(O11:O15) -> #REF! | P16: =SUM(P11:P15) -> #REF! | Q16: =SUM(Q11:Q15) -> #REF!
I17: מעוף | J17: קצין לוטם | K17: 37 | L17: =$B$22*$K17/$B$18 -> 27.151079 | M17: =$D$22*$K17/$B$18 -> 7.7194245 | N17: =SUM(L17:M17) -> 34.870504 | O17: 27 | P17: =COUNTIFS('חציון ב'!$C$10:$C$136,$I$17,'חציון ב'!$B$10:$B$136,$A$43)+COUNTIFS('חציון ב'!$C$10:$C$136,$I$17,'חציון ב'!$B$10:$B$136,$A$42) -> 7 | Q17: =SUM(O17:P17) -> 34 | R17: =IF(N17,Q17/N17,#N/A) -> 0.9750361 | S17: =IF(N18,Q18/N18,#N/A) -> 0.98364231 | T17: =IF(N19,Q19/N19,#N/A) -> #REF! | U17: =IF(N20,Q20/N20,#N/A) -> 0.80918367 | V17: =IF(N21,Q21/N21,#N/A) -> 1.0196078
A18: סה"כ | B18: =SUM(B4:B17) -> 139 | C18: =SUM(C4:C17) -> 164 | D18: =SUM(D4:D17) -> 90 | E18: =SUM(E4:E17) -> 122 | F18: =SUM(F4:F17) -> 52 | J18: נגד לוטם | K18: 42 | L18: =$B$23*$K18/$C$18 -> 26.121951 | M18: =$D$23*$K18/$C$18 -> 7.4268293 | N18: =SUM(L18:M18) -> 33.54878 | O18: 26 | P18: 7 | Q18: =SUM(O18:P18) -> 33
J19: מפקד 782 | K19: 15 | L19: 8.6 | M19: 2.5 | N19: =SUM(L19:M19) -> 11.1 | O19: =COUNTIF('חציון ב'!#REF!,$I$17)-$P$19 -> #REF! | P19: 3 | Q19: =SUM(O19:P19) -> #REF!
J20: ק.תורן 782 | K20: =E$6 -> 40 | L20: =$B$25*E$6/$E$18 -> 12.459016 | M20: =$D$25*K20/$E$18 -> 3.6065574 | N20: =SUM(L20:M20) -> 16.065574 | O20: 11 | P20: 2 | Q20: =SUM(O20:P20) -> 13
A21: תפקיד | B21: חול | D21: שישי-שבת | J21: תורן שער+טרמפיאדות | K21: =F$6 -> 8 | L21: =$B$26*$K21/$F$18 -> 7.8461538 | M21: =$D$26*$K21/$F$18 -> 0 | N21: =SUM(L21:M21) -> 7.8461538 | O21: 8 | P21: =COUNTIFS('חציון ב'!$C$397:$C$447,$I$17,'חציון ב'!$B$397:$B$447,$A$43)+COUNTIFS('חציון ב'!$C$397:$C$447,$I$17,'חציון ב'!$B$397:$B$447,$A$42) -> 0 | Q21: =SUM(O21:P21) -> 8
A22: קצין לוטם | B22: 102 | D22: 29 | J22: סה"כ | K22: =SUM(K17:K19,K21) -> 102 | L22: =SUM(L17:L21) -> 82.178201 | M22: =SUM(M17:M21) -> 21.252811 | N22: =SUM(L22:M22) -> 103.43101 | O22: =SUM(O17:O21) -> #REF! | P22: =SUM(P17:P21) -> 19 | Q22: =SUM(Q17:Q21) -> #REF!
A23: נגד לוטם | B23: 102 | D23: 29 | I23: משא"ן | J23: קצין לוטם | K23: =B$7 -> 5 | L23: =$B$22*$K23/$B$18 -> 3.6690647 | M23: =$D$22*$K23/$B$18 -> 1.0431655 | N23: =SUM(L23:M23) -> 4.7122302 | O23: 4 | P23: =COUNTIFS('חציון ב'!$C$10:$C$136,$I$23,'חציון ב'!$B$10:$B$136,$A$43)+COUNTIFS('חציון ב'!$C$10:$C$136,$I$23,'חציון ב'!$B$10:$B$136,$A$42) -> 1 | Q23: =SUM(O23:P23) -> 5 | R23: =IF(N23,Q23/N23,#N/A) -> 1.0610687 | S23: =IF(N24,Q24/N24,#N/A) -> #N/A | T23: =IF(N25,Q25/N25,#N/A) -> #N/A | U23: =IF(N26,Q26/N26,#N/A) -> 1.0809214 | V23: =IF(N27,Q27/N27,#N/A) -> 1.0196078
A24: מפקד 782 | B24: 50 | D24: 14 | J24: נגד לוטם | K24: =C$7 -> 0 | L24: =$B$23*$K24/$C$18 -> 0 | M24: =$D$23*$K24/$C$18 -> 0 | N24: =SUM(L24:M24) -> 0 | O24: =COUNTIF('חציון ב'!$C$145:$C$271,$I$23)-$P$24 -> 0 | P24: =COUNTIFS('חציון ב'!$C$145:$C$271,$I$23,'חציון ב'!$B$145:$B$271,$A$43)+COUNTIFS('חציון ב'!$C$145:$C$271,$I$23,'חציון ב'!$B$145:$B$271,$A$42) -> 0 | Q24: =SUM(O24:P24) -> 0
A25: ק.תורן 782 | B25: 38 | D25: 11 | J25: מפקד 782 | K25: =D$7 -> 0 | L25: =$B$24*$K25/$D$18 -> 0 | M25: =$D$24*$K25/$D$18 -> 0 | N25: =SUM(L25:M25) -> 0 | O25: =COUNTIF('חציון ב'!#REF!,$I$23)-$P$25 -> #REF! | P25: =COUNTIFS('חציון ב'!#REF!,$I$23,'חציון ב'!#REF!,$A$43)+COUNTIFS('חציון ב'!#REF!,$I$23,'חציון ב'!#REF!,$A$42) -> #REF! | Q25: =SUM(O25:P25) -> #REF!
A26: תורן שער+טרמפיאדות | B26: 51 | J26: ק.תורן 782 | K26: =E$7 -> 5 | L26: 5.1 | M26: =$D$25*K26/$E$18 -> 0.45081967 | N26: =SUM(L26:M26) -> 5.5508197 | O26: 5 | P26: 1 | Q26: =SUM(O26:P26) -> 6
J27: תורן שער+טרמפיאדות | K27: =F$7 -> 2 | L27: =$B$26*$K27/$F$18 -> 1.9615385 | M27: =$D$26*$K27/$F$18 -> 0 | N27: =SUM(L27:M27) -> 1.9615385 | O27: 2 | P27: =COUNTIFS('חציון ב'!$C$397:$C$447,$I$23,'חציון ב'!$B$397:$B$447,$A$43)+COUNTIFS('חציון ב'!$C$397:$C$447,$I$23,'חציון ב'!$B$397:$B$447,$A$42) -> 0 | Q27: =SUM(O27:P27) -> 2
J28: סה"כ | K28: =SUM(K23:K27) -> 12 | L28: =SUM(L23:L27) -> 10.730603 | M28: =SUM(M23:M27) -> 1.4939851 | N28: =SUM(L28:M28) -> 12.224588 | O28: =SUM(O23:O27) -> #REF! | P28: =SUM(P23:P27) -> #REF! | Q28: =SUM(Q23:Q27) -> #REF!
I29: מצו"ב | J29: קצין לוטם | K29: =B$8 -> 58 | L29: =$B$22*$K29/$B$18 -> 42.561151 | M29: =$D$22*$K29/$B$18 -> 12.100719 | N29: =SUM(L29:M29) -> 54.661871 | O29: =COUNTIF('חציון ב'!$C$10:$C$136,$I$29)-$P$29 -> 43 | P29: =COUNTIFS('חציון ב'!$C$10:$C$136,$I$29,'חציון ב'!$B$10:$B$136,$A$43)+COUNTIFS('חציון ב'!$C$10:$C$136,$I$29,'חציון ב'!$B$10:$B$136,$A$42) -> 11 | Q29: =SUM(O29:P29) -> 54 | R29: =IF(N29,Q29/N29,#N/A) -> 0.98789155 | S29: =IF(N30,Q30/N30,#N/A) -> 0.88097258 | T29: =IF(N31,Q31/N31,#N/A) -> #REF! | U29: =IF(N32,Q32/N32,#N/A) -> 0 | V29: =IF(N33,Q33/N33,#N/A) -> 0.66911765
J30: נגד לוטם | K30: =C$8 -> 81 | L30: =$B$23*$K30/$C$18 -> 50.378049 | M30: =$D$23*$K30/$C$18 -> 14.323171 | N30: =SUM(L30:M30) -> 64.70122 | O30: =COUNTIF('חציון ב'!$C$145:$C$271,$I$29)-$P$30 -> 46 | P30: =COUNTIFS('חציון ב'!$C$145:$C$271,$I$29,'חציון ב'!$B$145:$B$271,$A$43)+COUNTIFS('חציון ב'!$C$145:$C$271,$I$29,'חציון ב'!$B$145:$B$271,$A$42) -> 11 | Q30: =SUM(O30:P30) -> 57
J31: מפקד 782 | K31: =D$8 -> 45 | L31: =$B$24*$K31/$D$18 -> 25 | M31: =$D$24*$K31/$D$18 -> 7 | N31: =SUM(L31:M31) -> 32 | O31: =COUNTIF('חציון ב'!#REF!,$I$29)-$P$31 -> #REF! | P31: 7 | Q31: =SUM(O31:P31) -> #REF!
J32: ק.תורן 782 | K32: =E$8 -> 37 | L32: =$B$25*K32/$E$18 -> 11.52459 | M32: =$D$25*K32/$E$18 -> 3.3360656 | N32: =SUM(L32:M32) -> 14.860656 | O32: =COUNTIF('חציון ב'!$L$144:$L$231,$I$29)-$P$32 -> -3 | P32: 3 | Q32: =SUM(O32:P32) -> 0
J33: תורן שער+טרמפיאדות | K33: =F$8 -> 32 | L33: =$B$26*$K33/$F$18 -> 31.384615 | M33: =$D$26*$K33/$F$18 -> 0 | N33: =SUM(L33:M33) -> 31.384615 | O33: =COUNTIF('חציון ב'!$C$397:$C$433,$I$29)-$P$33 -> 21 | P33: =COUNTIFS('חציון ב'!$C$397:$C$447,$I$29,'חציון ב'!$B$397:$B$447,$A$43)+COUNTIFS('חציון ב'!$C$397:$C$447,$I$29,'חציון ב'!$B$397:$B$447,$A$42) -> 0 | Q33: =SUM(O33:P33) -> 21
J34: סה"כ | K34: =SUM(K29:K33) -> 253 | L34: =SUM(L29:L33) -> 160.84841 | M34: =SUM(M29:M33) -> 36.759956 | N34: =SUM(L34:M34) -> 197.60836 | O34: =SUM(O29:O33) -> #REF! | P34: =SUM(P29:P33) -> 32 | Q34: =SUM(Q29:Q33) -> #REF!
I35: בטחון מידע | J35: קצין לוטם | K35: =B$9 -> 0 | L35: =$B$22*$K35/$B$18 -> 0 | M35: =$D$22*$K35/$B$18 -> 0 | N35: =SUM(L35:M35) -> 0 | O35: =COUNTIF('חציון ב'!$C$10:$C$136,$I$35)-$P$35 -> 0 | P35: =COUNTIFS('חציון ב'!$C$10:$C$136,$I$35,'חציון ב'!$B$10:$B$136,$A$43)+COUNTIFS('חציון ב'!$C$10:$C$136,$I$35,'חציון ב'!$B$10:$B$136,$A$42) -> 0 | Q35: =SUM(O35:P35) -> 0 | R35: =IF(N35,Q35/N35,#N/A) -> #N/A | S35: =IF(N36,Q36/N36,#N/A) -> #N/A | T35: =IF(N37,Q37/N37,#N/A) -> #N/A | U35: =IF(N38,Q38/N38,#N/A) -> #N/A | V35: =IF(N39,Q39/N39,#N/A) -> #N/A
J36: נגד לוטם | K36: =C$9 -> 0 | L36: =$B$23*$K36/$C$18 -> 0 | M36: =$D$23*$K36/$C$18 -> 0 | N36: =SUM(L36:M36) -> 0 | O36: =COUNTIF('חציון ב'!$C$145:$C$271,$I$35)-$P$36 -> 0 | P36: 0 | Q36: =SUM(O36:P36) -> 0
J37: מפקד 782 | K37: =D$9 -> 0 | L37: =$B$24*$K37/$D$18 -> 0 | M37: =$D$24*$K37/$D$18 -> 0 | N37: =SUM(L37:M37) -> 0 | O37: =COUNTIF('חציון ב'!#REF!,$I$35)-$P$37 -> #REF! | P37: =COUNTIFS('חציון ב'!#REF!,$I$35,'חציון ב'!#REF!,$A$43)+COUNTIFS('חציון ב'!#REF!,$I$41,'חציון ב'!#REF!,$A$42) -> #REF! | Q37: =SUM(O37:P37) -> #REF!
J38: ק.תורן 782 | K38: =E$9 -> 0 | L38: =$B$25*$K38/$F$18 -> 0 | M38: =$D$25*$K38/$F$18 -> 0 | N38: =SUM(L38:M38) -> 0 | O38: =COUNTIF('חציון ב'!$L$144:$L$231,$I$35)-$P$38 -> 0 | P38: =COUNTIFS('חציון ב'!$L$144:$L$231,$I$35,'חציון ב'!$K$144:$K$231,$A$43)+COUNTIFS('חציון ב'!$L$144:$L$231,$I$35,'חציון ב'!$K$144:$K$231,$A$42) -> 0 | Q38: =SUM(O38:P38) -> 0
J39: תורן שער+טרמפיאדות | K39: =F$9 -> 0 | L39: =$B$26*$K39/$F$18 -> 0 | M39: =$D$26*$K39/$F$18 -> 0 | N39: =SUM(L39:M39) -> 0 | O39: =COUNTIF('חציון ב'!$C$397:$C$433,$I$35)-$P$39 -> 0 | P39: =COUNTIFS('חציון ב'!$C$397:$C$447,$I$35,'חציון ב'!$B$397:$B$447,$A$43)+COUNTIFS('חציון ב'!$C$397:$C$447,$I$35,'חציון ב'!$B$397:$B$447,$A$42) -> 0 | Q39: =SUM(O39:P39) -> 0
J40: סה"כ | K40: =SUM(K35:K39) -> 0 | L40: =SUM(L35:L39) -> 0 | M40: =SUM(M35:M39) -> 0 | N40: =SUM(L40:M40) -> 0 | O40: =SUM(O35:O39) -> #REF! | P40: =SUM(P35:P39) -> #REF! | Q40: =SUM(Q35:Q39) -> #REF!
A41: לא לגעת !!!!! | B41: נועם , לא לגעת ! | I41: מצפ"ן | J41: קצין לוטם | K41: =B$12 -> 7 | L41: =$B$22*$K41/$B$18 -> 5.1366906 | M41: =$D$22*$K41/$B$18 -> 1.4604317 | N41: =SUM(L41:M41) -> 6.5971223 | O41: =COUNTIF('חציון ב'!$C$10:$C$136,$I$41)-$P$41 -> 5 | P41: =COUNTIFS('חציון ב'!$C$10:$C$136,$I$41,'חציון ב'!$B$10:$B$136,$A$43)+COUNTIFS('חציון ב'!$C$10:$C$136,$I$41,'חציון ב'!$B$10:$B$136,$A$42) -> 2 | Q41: =SUM(O41:P41) -> 7 | R41: =IF(N41,Q41/N41,#N/A) -> 1.0610687 | S41: =IF(N42,Q42/N42,#N/A) -> 1.0015267 | T41: =IF(N43,Q43/N43,#N/A) -> #REF! | U41: =IF(N44,Q44/N44,#N/A) -> 1.0612245 | V41: =IF(N45,Q45/N45,#N/A) -> 1.0196078
A42: סופש | J42: נגד לוטם | K42: =C$12 -> 15 | L42: =$B$23*$K42/$C$18 -> 9.3292683 | M42: =$D$23*$K42/$C$18 -> 2.652439 | N42: =SUM(L42:M42) -> 11.981707 | O42: 9 | P42: =COUNTIFS('חציון ב'!$C$145:$C$271,$I$41,'חציון ב'!$B$145:$B$271,$A$43)+COUNTIFS('חציון ב'!$C$145:$C$271,$I$41,'חציון ב'!$B$145:$B$271,$A$42) -> 3 | Q42: =SUM(O42:P42) -> 12
...

Sheet רבעון
